---
title: "AttributeError: 'async_generator' object has no attribute 'post'エラーの解消法"
date: '2023-05-21'
thumbnail: 'https://github.com/Tatsurou-Yajima/tech-blog-by-t-yajima/assets/44424270/f0400954-d806-4191-b3dc-861d19583d0f'
---

![image](https://github.com/Tatsurou-Yajima/tech-blog-by-t-yajima/assets/44424270/f0400954-d806-4191-b3dc-861d19583d0f)

# AttributeError: 'async_generator' object has no attribute 'post'エラーの解消法

## 発生したエラー

Pythonのテストフレームワークである`Pytest`を使用中、以下のエラーに遭遇しました。

```log:ターミナル
AttributeError: 'async_generator' object has no attribute 'post'
```

ちなみに、テスト実行コマンドは以下のとおりです。

```docker:テスト実行コマンド
docker compose run --entrypoint "poetry run pytest" demo-app
```

## 解消法

フィクスチャを以下のように修正します。

### 修正前

```python
@pytest.fixture
async def async_client() -> AsyncClient:
```

### 修正後

```python
import pytest_asyncio

@pytest_asyncio.fixture
async def async_client() -> AsyncClient:
```

`pytest_asyncio`を使用することでエラーを解消できます。

## 原因

`asyncio_mode`のデフォルト値が変わったことが原因のようです。

https://github.com/pytest-dev/pytest-asyncio/releases

↓参考にさせていただきました！

https://www.beex-inc.com/blog/rejoin-nasu

